<?xml version="1.0" encoding="utf-8"?>
<!-- This URDF was automatically created by SolidWorks to URDF Exporter! Originally created by Stephen Brawner (brawner@gmail.com) 
     Commit Version: 1.5.1-0-g916b5db  Build Version: 1.5.7152.31018
     For more information, please see http://wiki.ros.org/sw_urdf_exporter -->
<robot
  name="fairino20_v6_robot">
  <link
    name="base_link">
    <inertial>
      <origin
        xyz="-2.1681E-05 -6.0648E-05 0.043457"
        rpy="0 0 0" />
      <mass
        value="9.2502" />
      <inertia
        ixx="0.034499"
        ixy="1.6641E-05"
        ixz="-7.478E-06"
        iyy="0.034518"
        iyz="-2.0849E-05"
        izz="0.05496" />
    </inertial>
    <visual>
      <origin
        xyz="0 0 0"
        rpy="0 0 0" />
      <geometry>
        <mesh
          filename="package://fairino_description/meshes/fairino20_v6/base_link.STL" />
      </geometry>
      <material
        name="">
        <color
          rgba="0.89804 0.91765 0.92941 1" />
      </material>
    </visual>
    <collision>
      <origin
        xyz="0 0 0"
        rpy="0 0 0" />
      <geometry>
        <mesh
          filename="package://fairino_description/meshes/fairino20_v6/base_link.STL" />
      </geometry>
    </collision>
  </link>
  <link
    name="shoulder_link">
    <inertial>
      <origin
        xyz="3.9254E-07 -0.010323 0.21287"
        rpy="0 0 0" />
      <mass
        value="19.459" />
      <inertia
        ixx="0.1323"
        ixy="1.0103E-06"
        ixz="-5.944E-07"
        iyy="0.12371"
        iyz="0.00042374"
        izz="0.10228" />
    </inertial>
    <visual>
      <origin
        xyz="0 0 0"
        rpy="0 0 0" />
      <geometry>
        <mesh
          filename="package://fairino_description/meshes/fairino20_v6/shoulder_link.STL" />
      </geometry>
      <material
        name="">
        <color
          rgba="0.89804 0.91765 0.92941 1" />
      </material>
    </visual>
    <collision>
      <origin
        xyz="0 0 0"
        rpy="0 0 0" />
      <geometry>
        <mesh
          filename="package://fairino_description/meshes/fairino20_v6/shoulder_link.STL" />
      </geometry>
    </collision>
  </link>
  <joint
    name="j1"
    type="revolute">
    <origin
      xyz="0 0 0"
      rpy="0 0 0" />
    <parent
      link="base_link" />
    <child
      link="shoulder_link" />
    <axis
      xyz="0 0 1" />
    <limit
      lower="-3.0543"
      upper="3.0543"
      effort="150"
      velocity="3.15" />
    <calibration
      rising="0"
      falling="0" />
    <dynamics
      damping="0"
      friction="0" />
    <safety_controller
      soft_upper_limit="3.0543261"
      soft_lower_limit="-3.0543261"
      k_position="100.0"
      k_velocity="40.0" />
  </joint>
  <link
    name="upperarm_link">
    <inertial>
      <origin
        xyz="-0.42217 4.2066E-06 0.22678"
        rpy="0 0 0" />
      <mass
        value="66.724" />
      <inertia
        ixx="0.2685"
        ixy="4.4967E-05"
        ixz="-0.0061696"
        iyy="8.9785"
        iyz="-8.1844E-06"
        izz="8.9379" />
    </inertial>
    <visual>
      <origin
        xyz="0 0 0"
        rpy="0 0 0" />
      <geometry>
        <mesh
          filename="package://fairino_description/meshes/fairino20_v6/upperarm_link.STL" />
      </geometry>
      <material
        name="">
        <color
          rgba="0.89804 0.91765 0.92941 1" />
      </material>
    </visual>
    <collision>
      <origin
        xyz="0 0 0"
        rpy="0 0 0" />
      <geometry>
        <mesh
          filename="package://fairino_description/meshes/fairino20_v6/upperarm_link.STL" />
      </geometry>
    </collision>
  </link>
  <joint
    name="j2"
    type="revolute">
    <origin
      xyz="0 0 0.215"
      rpy="1.5708 0 0" />
    <parent
      link="shoulder_link" />
    <child
      link="upperarm_link" />
    <axis
      xyz="0 0 1" />
    <limit
      lower="-4.6251"
      upper="1.4835"
      effort="150"
      velocity="3.15" />
    <calibration
      rising="0"
      falling="0" />
    <dynamics
      damping="0"
      friction="0" />
    <safety_controller
      soft_upper_limit="3.0543261"
      soft_lower_limit="-3.0543261"
      k_position="100.0"
      k_velocity="40.0" />
  </joint>
  <link
    name="forearm_link">
    <inertial>
      <origin
        xyz="-0.32102 1.1013E-06 0.036086"
        rpy="0 0 0" />
      <mass
        value="27.942" />
      <inertia
        ixx="0.067382"
        ixy="3.8412E-06"
        ixz="-0.060027"
        iyy="1.8359"
        iyz="1.1904E-06"
        izz="1.8258" />
    </inertial>
    <visual>
      <origin
        xyz="0 0 0"
        rpy="0 0 0" />
      <geometry>
        <mesh
          filename="package://fairino_description/meshes/fairino20_v6/forearm_link.STL" />
      </geometry>
      <material
        name="">
        <color
          rgba="0.89804 0.91765 0.92941 1" />
      </material>
    </visual>
    <collision>
      <origin
        xyz="0 0 0"
        rpy="0 0 0" />
      <geometry>
        <mesh
          filename="package://fairino_description/meshes/fairino20_v6/forearm_link.STL" />
      </geometry>
    </collision>
  </link>
  <joint
    name="j3"
    type="revolute">
    <origin
      xyz="-1 0 0"
      rpy="0 0 0" />
    <parent
      link="upperarm_link" />
    <child
      link="forearm_link" />
    <axis
      xyz="0 0 1" />
    <limit
      lower="-2.8274"
      upper="2.8274"
      effort="150"
      velocity="3.15" />
    <calibration
      rising="0"
      falling="0" />
    <dynamics
      damping="0"
      friction="0" />
    <safety_controller
      soft_upper_limit="3.0543261"
      soft_lower_limit="-3.0543261"
      k_position="100.0"
      k_velocity="40.0" />
  </joint>
  <link
    name="wrist1_link">
    <inertial>
      <origin
        xyz="-1.4575E-06 -0.0065782 0.16163"
        rpy="0 0 0" />
      <mass
        value="4.0932" />
      <inertia
        ixx="0.0093111"
        ixy="7.0183E-08"
        ixz="-1.2872E-07"
        iyy="0.0077482"
        iyz="0.00014273"
        izz="0.0089925" />
    </inertial>
    <visual>
      <origin
        xyz="0 0 0"
        rpy="0 0 0" />
      <geometry>
        <mesh
          filename="package://fairino_description/meshes/fairino20_v6/wrist1_link.STL" />
      </geometry>
      <material
        name="">
        <color
          rgba="0.89804 0.91765 0.92941 1" />
      </material>
    </visual>
    <collision>
      <origin
        xyz="0 0 0"
        rpy="0 0 0" />
      <geometry>
        <mesh
          filename="package://fairino_description/meshes/fairino20_v6/wrist1_link.STL" />
      </geometry>
    </collision>
  </link>
  <joint
    name="j4"
    type="revolute">
    <origin
      xyz="-0.716 0 0"
      rpy="0 0 0" />
    <parent
      link="forearm_link" />
    <child
      link="wrist1_link" />
    <axis
      xyz="0 0 1" />
    <limit
      lower="-4.6251"
      upper="1.4835"
      effort="28"
      velocity="3.2" />
    <calibration
      rising="0"
      falling="0" />
    <dynamics
      damping="0"
      friction="0" />
    <safety_controller
      soft_upper_limit="3.0543261"
      soft_lower_limit="-3.0543261"
      k_position="100.0"
      k_velocity="40.0" />
  </joint>
  <link
    name="wrist2_link">
    <inertial>
      <origin
        xyz="1.1445E-07 0.0065785 0.13363"
        rpy="0 0 0" />
      <mass
        value="4.0931" />
      <inertia
        ixx="0.0093111"
        ixy="3.2335E-09"
        ixz="-2.7278E-08"
        iyy="0.0077479"
        iyz="-0.00014267"
        izz="0.0089922" />
    </inertial>
    <visual>
      <origin
        xyz="0 0 0"
        rpy="0 0 0" />
      <geometry>
        <mesh
          filename="package://fairino_description/meshes/fairino20_v6/wrist2_link.STL" />
      </geometry>
      <material
        name="">
        <color
          rgba="0.89804 0.91765 0.92941 1" />
      </material>
    </visual>
    <collision>
      <origin
        xyz="0 0 0"
        rpy="0 0 0" />
      <geometry>
        <mesh
          filename="package://fairino_description/meshes/fairino20_v6/wrist2_link.STL" />
      </geometry>
    </collision>
  </link>
  <joint
    name="j5"
    type="revolute">
    <origin
      xyz="0 0 0.16601"
      rpy="1.5708 0 0" />
    <parent
      link="wrist1_link" />
    <child
      link="wrist2_link" />
    <axis
      xyz="0 0 1" />
    <limit
      lower="-3.0543"
      upper="3.0543"
      effort="28"
      velocity="3.2" />
    <calibration
      rising="0"
      falling="0" />
    <dynamics
      damping="0"
      friction="0" />
    <safety_controller
      soft_upper_limit="3.0543261"
      soft_lower_limit="-3.0543261"
      k_position="100.0"
      k_velocity="40.0" />
  </joint>
  <link
    name="wrist3_link">
    <inertial>
      <origin
        xyz="-0.00011258 -0.00010438 0.095779"
        rpy="0 0 0" />
      <mass
        value="1.1151" />
      <inertia
        ixx="0.0010481"
        ixy="3.93E-10"
        ixz="8.9623E-09"
        iyy="0.001048"
        iyz="1.7247E-09"
        izz="0.0018226" />
    </inertial>
    <visual>
      <origin
        xyz="0 0 0"
        rpy="0 0 0" />
      <geometry>
        <mesh
          filename="package://fairino_description/meshes/fairino20_v6/wrist3_link.STL" />
      </geometry>
      <material
        name="">
        <color
          rgba="0.79216 0.81961 0.93333 1" />
      </material>
    </visual>
    <collision>
      <origin
        xyz="0 0 0"
        rpy="0 0 0" />
      <geometry>
        <mesh
          filename="package://fairino_description/meshes/fairino20_v6/wrist3_link.STL" />
      </geometry>
    </collision>
  </link>
  <joint
    name="j6"
    type="revolute">
    <origin
      xyz="0 0 0.138"
      rpy="-1.5708 0 0" />
    <parent
      link="wrist2_link" />
    <child
      link="wrist3_link" />
    <axis
      xyz="0 0 1" />
    <limit
      lower="-3.0543"
      upper="3.0543"
      effort="28"
      velocity="3.2" />
    <calibration
      rising="0"
      falling="0" />
    <dynamics
      damping="0"
      friction="0" />
    <safety_controller
      soft_upper_limit="3.0543261"
      soft_lower_limit="-3.0543261"
      k_position="100.0"
      k_velocity="40.0" />
  </joint>
</robot>
