<?xml version="1.0" encoding="utf-8"?>
<!-- This URDF was automatically created by SolidWorks to URDF Exporter! Originally created by Stephen Brawner (brawner@gmail.com) 
     Commit Version: 1.5.1-0-g916b5db  Build Version: 1.5.7152.31018
     For more information, please see http://wiki.ros.org/sw_urdf_exporter -->
<robot
  name="fairino16_v6_robot">
  <link
    name="base_link">
    <inertial>
      <origin
        xyz="-0.00017171 -0.00016075 0.041272"
        rpy="0 0 0" />
      <mass
        value="1.6231" />
      <inertia
        ixx="0.0039513"
        ixy="1.1032E-05"
        ixz="-1.0078E-05"
        iyy="0.0039509"
        iyz="-9.408E-06"
        izz="0.0063729" />
    </inertial>
    <visual>
      <origin
        xyz="0 0 0"
        rpy="0 0 0" />
      <geometry>
        <mesh
          filename="package://fairino_description/meshes/fairino16_v6/base_link.STL" />
      </geometry>
      <material
        name="">
        <color
          rgba="0.89804 0.91765 0.92941 1" />
      </material>
    </visual>
    <collision>
      <origin
        xyz="0 0 0"
        rpy="0 0 0" />
      <geometry>
        <mesh
          filename="package://fairino_description/meshes/fairino16_v6/base_link.STL" />
      </geometry>
    </collision>
  </link>
  <link
    name="shoulder_link">
    <inertial>
      <origin
        xyz="2.6949E-07 -0.0077161 0.17504"
        rpy="0 0 0" />
      <mass
        value="3.7152" />
      <inertia
        ixx="0.015538"
        ixy="-6.8007E-08"
        ixz="-8.8038E-08"
        iyy="0.014566"
        iyz="0.00023847"
        izz="0.012006" />
    </inertial>
    <visual>
      <origin
        xyz="0 0 0"
        rpy="0 0 0" />
      <geometry>
        <mesh
          filename="package://fairino_description/meshes/fairino16_v6/shoulder_link.STL" />
      </geometry>
      <material
        name="">
        <color
          rgba="0.89804 0.91765 0.92941 1" />
      </material>
    </visual>
    <collision>
      <origin
        xyz="0 0 0"
        rpy="0 0 0" />
      <geometry>
        <mesh
          filename="package://fairino_description/meshes/fairino16_v6/shoulder_link.STL" />
      </geometry>
    </collision>
  </link>
  <joint
    name="j1"
    type="revolute">
    <origin
      xyz="0 0 0"
      rpy="0 0 0" />
    <parent
      link="base_link" />
    <child
      link="shoulder_link" />
    <axis
      xyz="0 0 1" />
    <limit
      lower="-3.0543"
      upper="3.0543"
      effort="150"
      velocity="3.15" />
    <calibration
      rising="0"
      falling="0" />
    <dynamics
      damping="0"
      friction="0" />
    <safety_controller
      soft_upper_limit="3.0543261"
      soft_lower_limit="-3.0543261"
      k_position="100.0"
      k_velocity="40.0" />
  </joint>
  <link
    name="upperarm_link">
    <inertial>
      <origin
        xyz="-0.20845 -1.0388E-06 0.18245"
        rpy="0 0 0" />
      <mass
        value="9.4622" />
      <inertia
        ixx="0.025921"
        ixy="2.097E-07"
        ixz="0.0025747"
        iyy="0.37903"
        iyz="1.3969E-07"
        izz="0.37439" />
    </inertial>
    <visual>
      <origin
        xyz="0 0 0"
        rpy="0 0 0" />
      <geometry>
        <mesh
          filename="package://fairino_description/meshes/fairino16_v6/upperarm_link.STL" />
      </geometry>
      <material
        name="">
        <color
          rgba="0.89804 0.91765 0.92941 1" />
      </material>
    </visual>
    <collision>
      <origin
        xyz="0 0 0"
        rpy="0 0 0" />
      <geometry>
        <mesh
          filename="package://fairino_description/meshes/fairino16_v6/upperarm_link.STL" />
      </geometry>
    </collision>
  </link>
  <joint
    name="j2"
    type="revolute">
    <origin
      xyz="0 0 0.18"
      rpy="1.5708 0 0" />
    <parent
      link="shoulder_link" />
    <child
      link="upperarm_link" />
    <axis
      xyz="0 0 1" />
    <limit
      lower="-4.6251"
      upper="1.4835"
      effort="150"
      velocity="3.15" />
    <calibration
      rising="0"
      falling="0" />
    <dynamics
      damping="0"
      friction="0" />
    <safety_controller
      soft_upper_limit="3.0543261"
      soft_lower_limit="-3.0543261"
      k_position="100.0"
      k_velocity="40.0" />
  </joint>
  <link
    name="forearm_link">
    <inertial>
      <origin
        xyz="-0.23441 5.6569E-07 0.048131"
        rpy="0 0 0" />
      <mass
        value="2.9964" />
      <inertia
        ixx="0.003827"
        ixy="-1.6004E-07"
        ixz="-0.0011373"
        iyy="0.054019"
        iyz="-5.5129E-08"
        izz="0.053512" />
    </inertial>
    <visual>
      <origin
        xyz="0 0 0"
        rpy="0 0 0" />
      <geometry>
        <mesh
          filename="package://fairino_description/meshes/fairino16_v6/forearm_link.STL" />
      </geometry>
      <material
        name="">
        <color
          rgba="0.89804 0.91765 0.92941 1" />
      </material>
    </visual>
    <collision>
      <origin
        xyz="0 0 0"
        rpy="0 0 0" />
      <geometry>
        <mesh
          filename="package://fairino_description/meshes/fairino16_v6/forearm_link.STL" />
      </geometry>
    </collision>
  </link>
  <joint
    name="j3"
    type="revolute">
    <origin
      xyz="-0.52 0 0"
      rpy="0 0 0" />
    <parent
      link="upperarm_link" />
    <child
      link="forearm_link" />
    <axis
      xyz="0 0 1" />
    <limit
      lower="-2.8274"
      upper="2.8274"
      effort="150"
      velocity="3.15" />
    <calibration
      rising="0"
      falling="0" />
    <dynamics
      damping="0"
      friction="0" />
    <safety_controller
      soft_upper_limit="3.0543261"
      soft_lower_limit="-3.0543261"
      k_position="100.0"
      k_velocity="40.0" />
  </joint>
  <link
    name="wrist1_link">
    <inertial>
      <origin
        xyz="2.4949E-07 -0.002597 0.1549"
        rpy="0 0 0" />
      <mass
        value="2.1573" />
      <inertia
        ixx="0.0033086"
        ixy="1.2835E-08"
        ixz="6.0662E-08"
        iyy="0.0024933"
        iyz="3.9256E-05"
        izz="0.003143" />
    </inertial>
    <visual>
      <origin
        xyz="0 0 0"
        rpy="0 0 0" />
      <geometry>
        <mesh
          filename="package://fairino_description/meshes/fairino16_v6/wrist1_link.STL" />
      </geometry>
      <material
        name="">
        <color
          rgba="0.89804 0.91765 0.92941 1" />
      </material>
    </visual>
    <collision>
      <origin
        xyz="0 0 0"
        rpy="0 0 0" />
      <geometry>
        <mesh
          filename="package://fairino_description/meshes/fairino16_v6/wrist1_link.STL" />
      </geometry>
    </collision>
  </link>
  <joint
    name="j4"
    type="revolute">
    <origin
      xyz="-0.4 0 0"
      rpy="0 0 0" />
    <parent
      link="forearm_link" />
    <child
      link="wrist1_link" />
    <axis
      xyz="0 0 1" />
    <limit
      lower="-4.6251"
      upper="1.4835"
      effort="28"
      velocity="3.2" />
    <calibration
      rising="0"
      falling="0" />
    <dynamics
      damping="0"
      friction="0" />
    <safety_controller
      soft_upper_limit="3.0543261"
      soft_lower_limit="-3.0543261"
      k_position="100.0"
      k_velocity="40.0" />
  </joint>
  <link
    name="wrist2_link">
    <inertial>
      <origin
        xyz="-2.4949E-07 0.002597 0.1099"
        rpy="0 0 0" />
      <mass
        value="2.1573" />
      <inertia
        ixx="0.0033086"
        ixy="1.2835E-08"
        ixz="-6.0662E-08"
        iyy="0.0024933"
        iyz="-3.9256E-05"
        izz="0.003143" />
    </inertial>
    <visual>
      <origin
        xyz="0 0 0"
        rpy="0 0 0" />
      <geometry>
        <mesh
          filename="package://fairino_description/meshes/fairino16_v6/wrist2_link.STL" />
      </geometry>
      <material
        name="">
        <color
          rgba="0.89804 0.91765 0.92941 1" />
      </material>
    </visual>
    <collision>
      <origin
        xyz="0 0 0"
        rpy="0 0 0" />
      <geometry>
        <mesh
          filename="package://fairino_description/meshes/fairino16_v6/wrist2_link.STL" />
      </geometry>
    </collision>
  </link>
  <joint
    name="j5"
    type="revolute">
    <origin
      xyz="0 0 0.159"
      rpy="1.5708 0 0" />
    <parent
      link="wrist1_link" />
    <child
      link="wrist2_link" />
    <axis
      xyz="0 0 1" />
    <limit
      lower="-3.0543"
      upper="3.0543"
      effort="28"
      velocity="3.2" />
    <calibration
      rising="0"
      falling="0" />
    <dynamics
      damping="0"
      friction="0" />
    <safety_controller
      soft_upper_limit="3.0543261"
      soft_lower_limit="-3.0543261"
      k_position="100.0"
      k_velocity="40.0" />
  </joint>
  <link
    name="wrist3_link">
    <inertial>
      <origin
        xyz="-8.7063E-06 -3.2122E-05 0.082426"
        rpy="0 0 0" />
      <mass
        value="0.20145" />
      <inertia
        ixx="0.0001117"
        ixy="9.1303E-11"
        ixz="6.3367E-09"
        iyy="0.00011182"
        iyz="9.9213E-08"
        izz="0.00016776" />
    </inertial>
    <visual>
      <origin
        xyz="0 0 0"
        rpy="0 0 0" />
      <geometry>
        <mesh
          filename="package://fairino_description/meshes/fairino16_v6/wrist3_link.STL" />
      </geometry>
      <material
        name="">
        <color
          rgba="0.89804 0.91765 0.92941 1" />
      </material>
    </visual>
    <collision>
      <origin
        xyz="0 0 0"
        rpy="0 0 0" />
      <geometry>
        <mesh
          filename="package://fairino_description/meshes/fairino16_v6/wrist3_link.STL" />
      </geometry>
    </collision>
  </link>
  <joint
    name="j6"
    type="revolute">
    <origin
      xyz="0 0 0.114"
      rpy="-1.5708 0 0" />
    <parent
      link="wrist2_link" />
    <child
      link="wrist3_link" />
    <axis
      xyz="0 0 1" />
    <limit
      lower="-3.0543"
      upper="3.0543"
      effort="28"
      velocity="3.2" />
    <calibration
      rising="0"
      falling="0" />
    <dynamics
      damping="0"
      friction="0" />
    <safety_controller
      soft_upper_limit="3.0543261"
      soft_lower_limit="-3.0543261"
      k_position="100.0"
      k_velocity="40.0" />
  </joint>
</robot>
