<?xml version="1.0" encoding="utf-8"?>
<!-- This URDF was automatically created by SolidWorks to URDF Exporter! Originally created by Stephen Brawner (brawner@gmail.com) 
     Commit Version: 1.5.1-0-g916b5db  Build Version: 1.5.7152.31018
     For more information, please see http://wiki.ros.org/sw_urdf_exporter -->
<robot
  name="FR3WML">
  <link
    name="base_link">
    <inertial>
      <origin
        xyz="-3.544E-05 0.0018522 0.036159"
        rpy="0 0 0" />
      <mass
        value="1.5602" />
      <inertia
        ixx="0.0019224"
        ixy="9.1835E-06"
        ixz="4.1178E-07"
        iyy="0.0017389"
        iyz="-5.5244E-05"
        izz="0.0020474" />
    </inertial>
    <visual>
      <origin
        xyz="0 0 0"
        rpy="0 0 0" />
      <geometry>
        <mesh
          filename="../meshes/FR3WML/visual/base_link.dae" />
      </geometry>
      <material
        name="">
        <color
          rgba="0.89804 0.91765 0.92941 1" />
      </material>
    </visual>
    <collision>
      <origin
        xyz="0 0 0"
        rpy="0 0 0" />
      <geometry>
        <mesh
          filename="../meshes/FR3WML/collision/base_link.STL" />
      </geometry>
    </collision>
  </link>
  <link
    name="shoulder_Link">
    <inertial>
      <origin
        xyz="0.00011018 -0.0051451 0.13509"
        rpy="0 0 0" />
      <mass
        value="2.199" />
      <inertia
        ixx="0.0036785"
        ixy="-7.6435E-08"
        ixz="-2.9566E-09"
        iyy="0.0035086"
        iyz="4.5889E-05"
        izz="0.0025295" />
    </inertial>
    <visual>
      <origin
        xyz="0 0 0"
        rpy="0 0 0" />
      <geometry>
        <mesh
          filename="../meshes/FR3WML/visual/shoulder_Link.dae" />
      </geometry>
      <material
        name="">
        <color
          rgba="0.89804 0.91765 0.92941 1" />
      </material>
    </visual>
    <collision>
      <origin
        xyz="0 0 0"
        rpy="0 0 0" />
      <geometry>
        <mesh
          filename="../meshes/FR3WML/collision/shoulder_Link.STL" />
      </geometry>
    </collision>
  </link>
  <joint
    name="j1"
    type="revolute">
    <origin
      xyz="0 0 0"
      rpy="0 0 0" />
    <parent
      link="base_link" />
    <child
      link="shoulder_Link" />
    <axis
      xyz="0 0 1" />
    <limit
      lower="-3.0543"
      upper="3.0543"
      effort="150"
      velocity="3.15" />
    <calibration
      rising="0"
      falling="0" />
    <dynamics
      damping="0"
      friction="0" />
    <safety_controller
      soft_upper="0"
      soft_lower="0"
      k_position="0"
      k_velocity="0" />
  </joint>
  <link
    name="upperarm_Link">
    <inertial>
      <origin
        xyz="-0.2125 -3.755E-09 0.11177"
        rpy="0 0 0" />
      <mass
        value="9.6868" />
      <inertia
        ixx="0.012228"
        ixy="1.5291E-07"
        ixz="2.1624E-10"
        iyy="0.054694"
        iyz="9.478E-10"
        izz="0.052396" />
    </inertial>
    <visual>
      <origin
        xyz="0 0 0"
        rpy="0 0 0" />
      <geometry>
        <mesh
          filename="../meshes/FR3WML/visual/upperarm_Link.dae" />
      </geometry>
      <material
        name="">
        <color
          rgba="0.89804 0.91765 0.92941 1" />
      </material>
    </visual>
    <collision>
      <origin
        xyz="0 0 0"
        rpy="0 0 0" />
      <geometry>
        <mesh
          filename="../meshes/FR3WML/collision/upperarm_Link.STL" />
      </geometry>
    </collision>
  </link>
  <joint
    name="j2"
    type="revolute">
    <origin
      xyz="0.00011097 -0.0010487 0.14"
      rpy="1.5708 0 0" />
    <parent
      link="shoulder_Link" />
    <child
      link="upperarm_Link" />
    <axis
      xyz="0 0 1" />
    <limit
      lower="-4.6251"
      upper="1.4835"
      effort="150"
      velocity="3.15" />
    <calibration
      rising="0"
      falling="0" />
    <dynamics
      damping="0"
      friction="0" />
    <safety_controller
      soft_upper="0"
      soft_lower="0"
      k_position="0"
      k_velocity="0" />
  </joint>
  <link
    name="forearm_Link">
    <inertial>
      <origin
        xyz="-0.20478 4.0476E-07 0.0033617"
        rpy="0 0 0" />
      <mass
        value="6.9034" />
      <inertia
        ixx="0.006477"
        ixy="-5.8827E-08"
        ixz="-0.00023367"
        iyy="0.031945"
        iyz="-4.2729E-08"
        izz="0.031214" />
    </inertial>
    <visual>
      <origin
        xyz="0 0 0"
        rpy="0 0 0" />
      <geometry>
        <mesh
          filename="../meshes/FR3WML/visual/forearm_Link.dae" />
      </geometry>
      <material
        name="">
        <color
          rgba="0.89804 0.91765 0.92941 1" />
      </material>
    </visual>
    <collision>
      <origin
        xyz="0 0 0"
        rpy="0 0 0" />
      <geometry>
        <mesh
          filename="../meshes/FR3WML/collision/forearm_Link.STL" />
      </geometry>
    </collision>
  </link>
  <joint
    name="j3"
    type="revolute">
    <origin
      xyz="-0.425 0 0"
      rpy="0 0 0" />
    <parent
      link="upperarm_Link" />
    <child
      link="forearm_Link" />
    <axis
      xyz="0 0 1" />
    <limit
      lower="-2.7925"
      upper="2.7925"
      effort="150"
      velocity="3.15" />
    <calibration
      rising="0"
      falling="0" />
    <dynamics
      damping="0"
      friction="0" />
    <safety_controller
      soft_upper="0"
      soft_lower="0"
      k_position="0"
      k_velocity="0" />
  </joint>
  <link
    name="wrist1_Link">
    <inertial>
      <origin
        xyz="1.8293E-07 -0.0045834 0.098137"
        rpy="0 0 0" />
      <mass
        value="1.5479" />
      <inertia
        ixx="0.0020458"
        ixy="1.985E-08"
        ixz="9.3074E-09"
        iyy="0.0014179"
        iyz="2.8396E-05"
        izz="0.0019413" />
    </inertial>
    <visual>
      <origin
        xyz="0 0 0"
        rpy="0 0 0" />
      <geometry>
        <mesh
          filename="../meshes/FR3WML/visual/wrist1_Link.dae" />
      </geometry>
      <material
        name="">
        <color
          rgba="0.89804 0.91765 0.92941 1" />
      </material>
    </visual>
    <collision>
      <origin
        xyz="0 0 0"
        rpy="0 0 0" />
      <geometry>
        <mesh
          filename="../meshes/FR3WML/collision/wrist1_Link.STL" />
      </geometry>
    </collision>
  </link>
  <joint
    name="j4"
    type="revolute">
    <origin
      xyz="-0.395 0 0"
      rpy="0 0 0" />
    <parent
      link="forearm_Link" />
    <child
      link="wrist1_Link" />
    <axis
      xyz="0 0 1" />
    <limit
      lower="-4.6251"
      upper="1.4835"
      effort="28"
      velocity="3.2" />
    <calibration
      rising="0"
      falling="0" />
    <dynamics
      damping="0"
      friction="0" />
    <safety_controller
      soft_upper="0"
      soft_lower="0"
      k_position="0"
      k_velocity="0" />
  </joint>
  <link
    name="wrist2_Link">
    <inertial>
      <origin
        xyz="-1.7487E-07 0.0045834 0.098137"
        rpy="0 0 0" />
      <mass
        value="1.5479" />
      <inertia
        ixx="0.0020458"
        ixy="1.985E-08"
        ixz="-9.3074E-09"
        iyy="0.0014179"
        iyz="-2.8396E-05"
        izz="0.0019413" />
    </inertial>
    <visual>
      <origin
        xyz="0 0 0"
        rpy="0 0 0" />
      <geometry>
        <mesh
          filename="../meshes/FR3WML/visual/wrist2_Link.dae" />
      </geometry>
      <material
        name="">
        <color
          rgba="0.89804 0.91765 0.92941 1" />
      </material>
    </visual>
    <collision>
      <origin
        xyz="0 0 0"
        rpy="0 0 0" />
      <geometry>
        <mesh
          filename="../meshes/FR3WML/collision/wrist2_Link.STL" />
      </geometry>
    </collision>
  </link>
  <joint
    name="j5"
    type="revolute">
    <origin
      xyz="0 0 0.102"
      rpy="1.5708 0 0" />
    <parent
      link="wrist1_Link" />
    <child
      link="wrist2_Link" />
    <axis
      xyz="0 0 1" />
    <limit
      lower="-3.0543"
      upper="3.0543"
      effort="28"
      velocity="3.2" />
    <calibration
      rising="0"
      falling="0" />
    <dynamics
      damping="0"
      friction="0" />
    <safety_controller
      soft_upper="0"
      soft_lower="0"
      k_position="0"
      k_velocity="0" />
  </joint>
  <link
    name="wrist3_Link">
    <inertial>
      <origin
        xyz="5.1954E-05 7.6931E-05 0.0766"
        rpy="0 0 0" />
      <mass
        value="0.52845" />
      <inertia
        ixx="0.00028205"
        ixy="2.1695E-07"
        ixz="-4.303E-07"
        iyy="0.00028201"
        iyz="-3.097E-07"
        izz="0.00041481" />
    </inertial>
    <visual>
      <origin
        xyz="0 0 0"
        rpy="0 0 0" />
      <geometry>
        <mesh
          filename="../meshes/FR3WML/visual/wrist3_Link.dae" />
      </geometry>
      <material
        name="">
        <color
          rgba="0.89804 0.91765 0.92941 1" />
      </material>
    </visual>
    <collision>
      <origin
        xyz="0 0 0"
        rpy="0 0 0" />
      <geometry>
        <mesh
          filename="../meshes/FR3WML/collision/wrist3_Link.STL" />
      </geometry>
    </collision>
  </link>
  <joint
    name="j6"
    type="revolute">
    <origin
      xyz="0 0 0.102"
      rpy="-1.5708 0 0" />
    <parent
      link="wrist2_Link" />
    <child
      link="wrist3_Link" />
    <axis
      xyz="0 0 1" />
    <limit
      lower="-6.2832"
      upper="6.2832"
      effort="28"
      velocity="3.2" />
    <calibration
      rising="0"
      falling="0" />
    <dynamics
      damping="0"
      friction="0" />
    <safety_controller
      soft_upper="0"
      soft_lower="0"
      k_position="0"
      k_velocity="0" />
  </joint>
  <!-- <link
    name="tool_Link">
    <inertial>
      <origin
        xyz="0.42882 0.086294 -0.13853"
        rpy="0 0 0" />
      <mass
        value="23.974" />
      <inertia
        ixx="0.13389"
        ixy="-0.023701"
        ixz="-0.015343"
        iyy="2.4117"
        iyz="0.0016672"
        izz="2.3665" />
    </inertial>
    <visual>
      <origin
        xyz="0 0 0"
        rpy="0 0 0" />
      <geometry>
        <mesh
          filename="../meshes/FR3WML/visual/tool_Link.STL" />
      </geometry>
      <material
        name="">
        <color
          rgba="1 1 1 1" />
      </material>
    </visual>
    <collision>
      <origin
        xyz="0 0 0"
        rpy="0 0 0" />
      <geometry>
        <mesh
          filename="../meshes/FR3WML/collision/tool_Link.STL" />
      </geometry>
    </collision>
  </link> -->
  <joint
    name="tool"
    type="fixed">
    <origin
      xyz="0 -0.00038104 0.1"
      rpy="0 0 0" />
    <parent
      link="wrist3_Link" />
    <child
      link="tool_Link" />
    <axis
      xyz="0 0 0" />
    <limit
      lower="0"
      upper="0"
      effort="0"
      velocity="0" />
    <calibration
      rising="0"
      falling="0" />
    <dynamics
      damping="0"
      friction="0" />
    <safety_controller
      soft_upper="0"
      soft_lower="0"
      k_position="0"
      k_velocity="0" />
  </joint>
</robot>