<?xml version="1.0" encoding="utf-8"?>
<!-- This URDF was automatically created by SolidWorks to URDF Exporter! Originally created by Stephen Brawner (brawner@gmail.com) 
     Commit Version: 1.5.1-0-g916b5db  Build Version: 1.5.7152.31018
     For more information, please see http://wiki.ros.org/sw_urdf_exporter -->
<robot
  name="FR5WM">
  <link
    name="base_link">
    <inertial>
      <origin
        xyz="-0.00049027 -0.00045095 0.032527"
        rpy="0 0 0" />
      <mass
        value="0.78393" />
      <inertia
        ixx="0.0013854"
        ixy="1.1455E-05"
        ixz="-1.0642E-05"
        iyy="0.0013849"
        iyz="-9.7435E-06"
        izz="0.001977" />
    </inertial>
    <visual>
      <origin
        xyz="0 0 0"
        rpy="0 0 0" />
      <geometry>
        <mesh
          filename="../meshes/FR5WM/visual/base_link.dae" />
      </geometry>
      <material
        name="">
        <color
          rgba="1 1 1 1" />
      </material>
    </visual>
    <collision>
      <origin
        xyz="0 0 0"
        rpy="0 0 0" />
      <geometry>
        <mesh
          filename="../meshes/FR5WM/collision/base_link.STL" />
      </geometry>
    </collision>
  </link>
  <link
    name="shoulder_Link">
    <inertial>
      <origin
        xyz="-3.6139E-07 -0.0024164 0.13521"
        rpy="0 0 0" />
      <mass
        value="2.26" />
      <inertia
        ixx="0.0033227"
        ixy="-5.0648E-08"
        ixz="-6.3401E-09"
        iyy="0.0032419"
        iyz="4.3768E-05"
        izz="0.0023129" />
    </inertial>
    <visual>
      <origin
        xyz="0 0 0"
        rpy="0 0 0" />
      <geometry>
        <mesh
          filename="../meshes/FR5WM/visual/shoulder_Link.dae" />
      </geometry>
      <material
        name="">
        <color
          rgba="1 1 1 1" />
      </material>
    </visual>
    <collision>
      <origin
        xyz="0 0 0"
        rpy="0 0 0" />
      <geometry>
        <mesh
          filename="../meshes/FR5WM/collision/shoulder_Link.STL" />
      </geometry>
    </collision>
  </link>
  <joint
    name="j1"
    type="revolute">
    <origin
      xyz="0 0 0"
      rpy="0 0 0" />
    <parent
      link="base_link" />
    <child
      link="shoulder_Link" />
    <axis
      xyz="0 0 1" />
    <limit
      lower="-3.124"
      upper="3.124"
      effort="150"
      velocity="3.15" />
    <calibration
      rising="0"
      falling="0" />
    <dynamics
      damping="0"
      friction="0" />
    <safety_controller
      soft_upper="0"
      soft_lower="0"
      k_position="0"
      k_velocity="0" />
  </joint>
  <link
    name="upperarm_Link">
    <inertial>
      <origin
        xyz="-0.19609 1.3185E-07 0.11207"
        rpy="0 0 0" />
      <mass
        value="4.53" />
      <inertia
        ixx="0.0087492"
        ixy="7.5596E-08"
        ixz="1.1257E-05"
        iyy="0.045099"
        iyz="-4.721E-10"
        izz="0.043531" />
    </inertial>
    <visual>
      <origin
        xyz="0 0 0"
        rpy="0 0 0" />
      <geometry>
        <mesh
          filename="../meshes/FR5WM/visual/upperarm_Link.dae" />
      </geometry>
      <material
        name="">
        <color
          rgba="0.89804 0.91765 0.92941 1" />
      </material>
    </visual>
    <collision>
      <origin
        xyz="0 0 0"
        rpy="0 0 0" />
      <geometry>
        <mesh
          filename="../meshes/FR5WM/collision/upperarm_Link.STL" />
      </geometry>
    </collision>
  </link>
  <joint
    name="j2"
    type="revolute">
    <origin
      xyz="0 0 0.14"
      rpy="1.5708 0 0" />
    <parent
      link="shoulder_Link" />
    <child
      link="upperarm_Link" />
    <axis
      xyz="0 0 1" />
    <limit
      lower="-4.6949"
      upper="1.5533"
      effort="150"
      velocity="3.15" />
    <calibration
      rising="0"
      falling="0" />
    <dynamics
      damping="0"
      friction="0" />
    <safety_controller
      soft_upper="0"
      soft_lower="0"
      k_position="0"
      k_velocity="0" />
  </joint>
  <link
    name="forearm_Link">
    <inertial>
      <origin
        xyz="-0.00344 -1.5607E-07 0.014599"
        rpy="0 0 0" />
      <mass
        value="1.56" />
      <inertia
        ixx="0.0014524"
        ixy="6.8087E-09"
        ixz="-3.2511E-05"
        iyy="0.0020112"
        iyz="-2.4944E-08"
        izz="0.0019076" />
    </inertial>
    <visual>
      <origin
        xyz="0 0 0"
        rpy="0 0 0" />
      <geometry>
        <mesh
          filename="../meshes/FR5WM/visual/forearm_Link.dae" />
      </geometry>
      <material
        name="">
        <color
          rgba="0.89804 0.91765 0.92941 1" />
      </material>
    </visual>
    <collision>
      <origin
        xyz="0 0 0"
        rpy="0 0 0" />
      <geometry>
        <mesh
          filename="../meshes/FR5WM/collision/forearm_Link.STL" />
      </geometry>
    </collision>
  </link>
  <joint
    name="j3"
    type="revolute">
    <origin
      xyz="-0.42 0 0.001107"
      rpy="0 0 0" />
    <parent
      link="upperarm_Link" />
    <child
      link="forearm_Link" />
    <axis
      xyz="0 0 1" />
    <limit
      lower="-2.40855"
      upper="2.40855"
      effort="150"
      velocity="3.15" />
    <calibration
      rising="0"
      falling="0" />
    <dynamics
      damping="0"
      friction="0" />
    <safety_controller
      soft_upper="0"
      soft_lower="0"
      k_position="0"
      k_velocity="0" />
  </joint>
  <link
    name="wrist1_Link">
    <inertial>
      <origin
        xyz="0.0010775 -4.849E-07 0.23673"
        rpy="0 0 0" />
      <mass
        value="1.97" />
      <inertia
        ixx="0.054511"
        ixy="2.1827E-08"
        ixz="-0.0010509"
        iyy="0.055102"
        iyz="1.2523E-07"
        izz="0.0047409" />
    </inertial>
    <visual>
      <origin
        xyz="0 0 0"
        rpy="0 0 0" />
      <geometry>
        <mesh
          filename="../meshes/FR5WM/visual/wrist1_Link.dae" />
      </geometry>
      <material
        name="">
        <color
          rgba="0.89804 0.91765 0.92941 1" />
      </material>
    </visual>
    <collision>
      <origin
        xyz="0 0 0"
        rpy="0 0 0" />
      <geometry>
        <mesh
          filename="../meshes/FR5WM/collision/wrist1_Link.STL" />
      </geometry>
    </collision>
  </link>
  <joint
    name="j4"
    type="revolute">
    <origin
      xyz="0 0 0.010893"
      rpy="1.5708 0 -1.5708" />
    <parent
      link="forearm_Link" />
    <child
      link="wrist1_Link" />
    <axis
      xyz="0 0 1" />
    <limit
      lower="-3.124"
      upper="3.124"
      effort="28"
      velocity="3.2" />
    <calibration
      rising="0"
      falling="0" />
    <dynamics
      damping="0"
      friction="0" />
    <safety_controller
      soft_upper="0"
      soft_lower="0"
      k_position="0"
      k_velocity="0" />
  </joint>
  <link
    name="wrist2_Link">
    <inertial>
      <origin
        xyz="-0.00344 1.5604E-07 0.098294"
        rpy="0 0 0" />
      <mass
        value="1.56" />
      <inertia
        ixx="0.0014524"
        ixy="-6.8085E-09"
        ixz="3.2511E-05"
        iyy="0.0020112"
        iyz="-2.4945E-08"
        izz="0.0019076" />
    </inertial>
    <visual>
      <origin
        xyz="0 0 0"
        rpy="0 0 0" />
      <geometry>
        <mesh
          filename="../meshes/FR5WM/visual/wrist2_Link.dae" />
      </geometry>
      <material
        name="">
        <color
          rgba="1 1 1 1" />
      </material>
    </visual>
    <collision>
      <origin
        xyz="0 0 0"
        rpy="0 0 0" />
      <geometry>
        <mesh
          filename="../meshes/FR5WM/collision/wrist2_Link.STL" />
      </geometry>
    </collision>
  </link>
  <joint
    name="j5"
    type="revolute">
    <origin
      xyz="0 0 0.36"
      rpy="-1.5708 0 -1.5708" />
    <parent
      link="wrist1_Link" />
    <child
      link="wrist2_Link" />
    <axis
      xyz="0 0 1" />
    <limit
      lower="-1.5533"
      upper="4.6949"
      effort="28"
      velocity="3.2" />
    <calibration
      rising="0"
      falling="0" />
    <dynamics
      damping="0"
      friction="0" />
    <safety_controller
      soft_upper="0"
      soft_lower="0"
      k_position="0"
      k_velocity="0" />
  </joint>
  <link
    name="wrist3_Link">
    <inertial>
      <origin
        xyz="7.559E-05 1.3854E-05 -0.023381"
        rpy="0 0 0" />
      <mass
        value="0.35" />
      <inertia
        ixx="0.00028785"
        ixy="-2.0582E-09"
        ixz="-1.3892E-07"
        iyy="0.00028896"
        iyz="1.8115E-07"
        izz="0.00042655" />
    </inertial>
    <visual>
      <origin
        xyz="0 0 0"
        rpy="0 0 0" />
      <geometry>
        <mesh
          filename="../meshes/FR5WM/visual/wrist3_Link.dae" />
      </geometry>
      <material
        name="">
        <color
          rgba="1 1 1 1" />
      </material>
    </visual>
    <collision>
      <origin
        xyz="0 0 0"
        rpy="0 0 0" />
      <geometry>
        <mesh
          filename="../meshes/FR5WM/collision/wrist3_Link.STL" />
      </geometry>
    </collision>
  </link>
  <joint
    name="j6"
    type="revolute">
    <origin
      xyz="-0.1 0 0.102"
      rpy="-1.5708 0 1.5708" />
    <parent
      link="wrist2_Link" />
    <child
      link="wrist3_Link" />
    <axis
      xyz="0 0 1" />
    <limit
      lower="-3.124"
      upper="3.124"
      effort="28"
      velocity="3.2" />
    <calibration
      rising="0"
      falling="0" />
    <dynamics
      damping="0"
      friction="0" />
    <safety_controller
      soft_upper="0"
      soft_lower="0"
      k_position="0"
      k_velocity="0" />
  </joint>
  <joint
    name="tool"
    type="fixed">
    <origin
      xyz="0 0 0"
      rpy="0 0 1.570796" />
    <parent
      link="wrist3_Link" />
    <child
      link="gripper_Link" />
    <axis
      xyz="0 0 1" />
    <limit
      lower="-3.0543"
      upper="3.0543"
      effort="28"
      velocity="3.2" />
    <calibration
      rising="0"
      falling="0" />
    <dynamics
      damping="0"
      friction="0" />
    <safety_controller
      soft_upper="0"
      soft_lower="0"
      k_position="0"
      k_velocity="0" />
  </joint>
  <!-- <link
    name="gripper_Link">
    <inertial>
      <origin
        xyz="5.8427E-06 7.5807E-05 0.079126"
        rpy="0 0 0" />
      <mass
        value="0.52527" />
      <inertia
        ixx="0.00027801"
        ixy="-3.5346E-07"
        ixz="-1.7431E-07"
        iyy="0.00027736"
        iyz="-7.5888E-08"
        izz="0.00041582" />
    </inertial>
    <visual>
      <origin
        xyz="0 0 0"
        rpy="0 0 0" />
      <geometry>
        <mesh
          filename="../tool/gripper.dae" />
      </geometry>
      <material
        name="">
        <color
          rgba="0.89804 0.91765 0.92941 1" />
      </material>
    </visual>
    <collision>
      <origin
        xyz="0 0 0"
        rpy="0 0 0" />
      <geometry>
        <mesh
          filename="../tool/gripper.STL" />
      </geometry>
    </collision>
  </link> -->
</robot>